============================= test session starts =============================
platform win32 -- Python 3.13.1, pytest-8.3.5, pluggy-1.5.0 -- C:\v0.81\.venv\Scripts\python.exe
cachedir: .pytest_cache
rootdir: C:\v0.81
configfile: pytest.ini
plugins: spec-4.0.0
collecting ... ⚠️  Table missing: positions — creating...
⚠️  Table missing: alerts — creating...
⚠️  Table missing: wallets — creating...
⚠️  Table missing: prices — creating...
[05/25/25 15:05:08] INFO     ✅ ✅ Modifiers loaded into CalcServices ::       
                             [CalculationCore] @ 2025-05-25 15:05:08 →         
                             distanceWeight: 0.6, leverageWeight: 0.3,         
                             collateralWeight: 0.1                             
collected 80 items / 7 errors

=================================== ERRORS ====================================
_______ ERROR collecting tests/test_create_evaluate_portfolio_alerts.py _______
ImportError while importing test module 'C:\v0.81\tests\test_create_evaluate_portfolio_alerts.py'.
Hint: make sure your test modules/packages have valid Python names.
Traceback:
.venv\Lib\site-packages\_pytest\python.py:493: in importtestmodule
    mod = import_path(
.venv\Lib\site-packages\_pytest\pathlib.py:587: in import_path
    importlib.import_module(module_name)
C:\Users\bubba\AppData\Local\Programs\Python\Python313\Lib\importlib\__init__.py:88: in import_module
    return _bootstrap._gcd_import(name[level:], package, level)
<frozen importlib._bootstrap>:1387: in _gcd_import
    ???
<frozen importlib._bootstrap>:1360: in _find_and_load
    ???
<frozen importlib._bootstrap>:1331: in _find_and_load_unlocked
    ???
<frozen importlib._bootstrap>:935: in _load_unlocked
    ???
.venv\Lib\site-packages\_pytest\assertion\rewrite.py:185: in exec_module
    exec(co, module.__dict__)
tests\test_create_evaluate_portfolio_alerts.py:10: in <module>
    from alert_core.alert_service_manager import AlertServiceManager
E   ModuleNotFoundError: No module named 'alert_core.alert_service_manager'
______________ ERROR collecting tests/test_launch_pad_recover.py ______________
ImportError while importing test module 'C:\v0.81\tests\test_launch_pad_recover.py'.
Hint: make sure your test modules/packages have valid Python names.
Traceback:
.venv\Lib\site-packages\_pytest\python.py:493: in importtestmodule
    mod = import_path(
.venv\Lib\site-packages\_pytest\pathlib.py:587: in import_path
    importlib.import_module(module_name)
C:\Users\bubba\AppData\Local\Programs\Python\Python313\Lib\importlib\__init__.py:88: in import_module
    return _bootstrap._gcd_import(name[level:], package, level)
<frozen importlib._bootstrap>:1387: in _gcd_import
    ???
<frozen importlib._bootstrap>:1360: in _find_and_load
    ???
<frozen importlib._bootstrap>:1331: in _find_and_load_unlocked
    ???
<frozen importlib._bootstrap>:935: in _load_unlocked
    ???
.venv\Lib\site-packages\_pytest\assertion\rewrite.py:185: in exec_module
    exec(co, module.__dict__)
tests\test_launch_pad_recover.py:21: in <module>
    import launch_pad
launch_pad.py:18: in <module>
    from utils.startup_service import StartUpService
utils\startup_service.py:12: in <module>
    from utils.config_loader import save_config
E   ModuleNotFoundError: No module named 'utils.config_loader'
________________ ERROR collecting tests/test_portfolio_ale.py _________________
ImportError while importing test module 'C:\v0.81\tests\test_portfolio_ale.py'.
Hint: make sure your test modules/packages have valid Python names.
Traceback:
.venv\Lib\site-packages\_pytest\python.py:493: in importtestmodule
    mod = import_path(
.venv\Lib\site-packages\_pytest\pathlib.py:587: in import_path
    importlib.import_module(module_name)
C:\Users\bubba\AppData\Local\Programs\Python\Python313\Lib\importlib\__init__.py:88: in import_module
    return _bootstrap._gcd_import(name[level:], package, level)
<frozen importlib._bootstrap>:1387: in _gcd_import
    ???
<frozen importlib._bootstrap>:1360: in _find_and_load
    ???
<frozen importlib._bootstrap>:1331: in _find_and_load_unlocked
    ???
<frozen importlib._bootstrap>:935: in _load_unlocked
    ???
.venv\Lib\site-packages\_pytest\assertion\rewrite.py:185: in exec_module
    exec(co, module.__dict__)
tests\test_portfolio_ale.py:3: in <module>
    from core.core_imports import get_locker, log
E   ImportError: cannot import name 'get_locker' from 'core.core_imports' (C:\v0.81\core\core_imports.py)
_ ERROR collecting cyclone/tests/test_cyclone_step_create_portfolio_alerts.py _
cyclone\tests\test_cyclone_step_create_portfolio_alerts.py:11: in <module>
    cyclone = Cyclone()
E   TypeError: Cyclone.__init__() missing 1 required positional argument: 'monitor_core'
_ ERROR collecting cyclone/tests/test_cyclone_step_create_position_alerts.py __
cyclone\tests\test_cyclone_step_create_position_alerts.py:16: in <module>
    dl = DataLocker(str(DB_PATH))
E   NameError: name 'DataLocker' is not defined
_____ ERROR collecting cyclone/tests/test_cyclone_step_evaluate_alerts.py _____
cyclone\tests\test_cyclone_step_evaluate_alerts.py:14: in <module>
    cyclone = Cyclone()
E   TypeError: Cyclone.__init__() missing 1 required positional argument: 'monitor_core'
_____ ERROR collecting cyclone/tests/test_cyclone_step_market_updates.py ______
cyclone\tests\test_cyclone_step_market_updates.py:18: in <module>
    cyclone = Cyclone()
E   TypeError: Cyclone.__init__() missing 1 required positional argument: 'monitor_core'
============================== warnings summary ===============================
.venv\Lib\site-packages\_pytest\config\__init__.py:1441
  C:\v0.81\.venv\Lib\site-packages\_pytest\config\__init__.py:1441: PytestConfigWarning: Unknown config option: asyncio_mode
  
    self._warn_or_fail_if_strict(f"Unknown config option: {key}\n")

.venv\Lib\site-packages\pydantic\_internal\_config.py:295
  C:\v0.81\.venv\Lib\site-packages\pydantic\_internal\_config.py:295: PydanticDeprecatedSince20: Support for class-based `config` is deprecated, use ConfigDict instead. Deprecated in Pydantic V2.0 to be removed in V3.0. See Pydantic V2 Migration Guide at https://errors.pydantic.dev/2.10/migration/
    warnings.warn(DEPRECATION_MESSAGE, DeprecationWarning)

.venv\Lib\site-packages\pydantic\fields.py:1042
.venv\Lib\site-packages\pydantic\fields.py:1042
.venv\Lib\site-packages\pydantic\fields.py:1042
  C:\v0.81\.venv\Lib\site-packages\pydantic\fields.py:1042: PydanticDeprecatedSince20: Using extra keyword arguments on `Field` is deprecated and will be removed. Use `json_schema_extra` instead. (Extra keys: 'example'). Deprecated in Pydantic V2.0 to be removed in V3.0. See Pydantic V2 Migration Guide at https://errors.pydantic.dev/2.10/migration/
    warn(

.venv\Lib\site-packages\websockets\legacy\__init__.py:6
  C:\v0.81\.venv\Lib\site-packages\websockets\legacy\__init__.py:6: DeprecationWarning: websockets.legacy is deprecated; see https://websockets.readthedocs.io/en/stable/howto/upgrade.html for upgrade instructions
    warnings.warn(  # deprecated in 14.0 - 2024-11-09

tests\test_alert_enrichment.py:45
  C:\v0.81\tests\test_alert_enrichment.py:45: PytestUnknownMarkWarning: Unknown pytest.mark.asyncio - is this a typo?  You can register custom marks to avoid this warning - for details, see https://docs.pytest.org/en/stable/how-to/mark.html
    @pytest.mark.asyncio

tests\test_alert_enrichment.py:51
  C:\v0.81\tests\test_alert_enrichment.py:51: PytestUnknownMarkWarning: Unknown pytest.mark.asyncio - is this a typo?  You can register custom marks to avoid this warning - for details, see https://docs.pytest.org/en/stable/how-to/mark.html
    @pytest.mark.asyncio

tests\test_alert_enrichment.py:57
  C:\v0.81\tests\test_alert_enrichment.py:57: PytestUnknownMarkWarning: Unknown pytest.mark.asyncio - is this a typo?  You can register custom marks to avoid this warning - for details, see https://docs.pytest.org/en/stable/how-to/mark.html
    @pytest.mark.asyncio

tests\test_alert_enrichment.py:64
  C:\v0.81\tests\test_alert_enrichment.py:64: PytestUnknownMarkWarning: Unknown pytest.mark.asyncio - is this a typo?  You can register custom marks to avoid this warning - for details, see https://docs.pytest.org/en/stable/how-to/mark.html
    @pytest.mark.asyncio

tests\test_alert_enrichment.py:71
  C:\v0.81\tests\test_alert_enrichment.py:71: PytestUnknownMarkWarning: Unknown pytest.mark.asyncio - is this a typo?  You can register custom marks to avoid this warning - for details, see https://docs.pytest.org/en/stable/how-to/mark.html
    @pytest.mark.asyncio

tests\test_alert_enrichment.py:79
  C:\v0.81\tests\test_alert_enrichment.py:79: PytestUnknownMarkWarning: Unknown pytest.mark.asyncio - is this a typo?  You can register custom marks to avoid this warning - for details, see https://docs.pytest.org/en/stable/how-to/mark.html
    @pytest.mark.asyncio

tests\test_cyclone_alerts.py:10
  C:\v0.81\tests\test_cyclone_alerts.py:10: PytestUnknownMarkWarning: Unknown pytest.mark.asyncio - is this a typo?  You can register custom marks to avoid this warning - for details, see https://docs.pytest.org/en/stable/how-to/mark.html
    @pytest.mark.asyncio

tests\test_cyclone_alerts.py:21
  C:\v0.81\tests\test_cyclone_alerts.py:21: PytestUnknownMarkWarning: Unknown pytest.mark.asyncio - is this a typo?  You can register custom marks to avoid this warning - for details, see https://docs.pytest.org/en/stable/how-to/mark.html
    @pytest.mark.asyncio

tests\test_cyclone_alerts.py:32
  C:\v0.81\tests\test_cyclone_alerts.py:32: PytestUnknownMarkWarning: Unknown pytest.mark.asyncio - is this a typo?  You can register custom marks to avoid this warning - for details, see https://docs.pytest.org/en/stable/how-to/mark.html
    @pytest.mark.asyncio

tests\test_cyclone_market_udpates.py:11
  C:\v0.81\tests\test_cyclone_market_udpates.py:11: PytestUnknownMarkWarning: Unknown pytest.mark.asyncio - is this a typo?  You can register custom marks to avoid this warning - for details, see https://docs.pytest.org/en/stable/how-to/mark.html
    @pytest.mark.asyncio

tests\test_cyclone_position_updates.py:11
  C:\v0.81\tests\test_cyclone_position_updates.py:11: PytestUnknownMarkWarning: Unknown pytest.mark.asyncio - is this a typo?  You can register custom marks to avoid this warning - for details, see https://docs.pytest.org/en/stable/how-to/mark.html
    @pytest.mark.asyncio

tests\test_enrichment_travel_percent.py:29
  C:\v0.81\tests\test_enrichment_travel_percent.py:29: PytestUnknownMarkWarning: Unknown pytest.mark.asyncio - is this a typo?  You can register custom marks to avoid this warning - for details, see https://docs.pytest.org/en/stable/how-to/mark.html
    @pytest.mark.asyncio

tests\test_portfolio_alert_data_creation.py:29
  C:\v0.81\tests\test_portfolio_alert_data_creation.py:29: PytestUnknownMarkWarning: Unknown pytest.mark.asyncio - is this a typo?  You can register custom marks to avoid this warning - for details, see https://docs.pytest.org/en/stable/how-to/mark.html
    @pytest.mark.asyncio

tests\test_position_core_enrich.py:7
  C:\v0.81\tests\test_position_core_enrich.py:7: PytestUnknownMarkWarning: Unknown pytest.mark.asyncio - is this a typo?  You can register custom marks to avoid this warning - for details, see https://docs.pytest.org/en/stable/how-to/mark.html
    @pytest.mark.asyncio

test_core\test_core.py:13
  C:\v0.81\test_core\test_core.py:13: PytestCollectionWarning: cannot collect test class 'TestCore' because it has a __init__ constructor (from: tests/test_run_glob.py)
    class TestCore:

-- Docs: https://docs.pytest.org/en/stable/how-to/capture-warnings.html
=========================== short test summary info ===========================
ERROR tests/test_create_evaluate_portfolio_alerts.py
ERROR tests/test_launch_pad_recover.py
ERROR tests/test_portfolio_ale.py
ERROR cyclone/tests/test_cyclone_step_create_portfolio_alerts.py - TypeError: Cyclone.__init__() missing 1 required positional argument: 'monitor_core'
ERROR cyclone/tests/test_cyclone_step_create_position_alerts.py - NameError: name 'DataLocker' is not defined
ERROR cyclone/tests/test_cyclone_step_evaluate_alerts.py - TypeError: Cyclone.__init__() missing 1 required positional argument: 'monitor_core'
ERROR cyclone/tests/test_cyclone_step_market_updates.py - TypeError: Cyclone.__init__() missing 1 required positional argument: 'monitor_core'
!!!!!!!!!!!!!!!!!!! Interrupted: 7 errors during collection !!!!!!!!!!!!!!!!!!!
======================= 21 warnings, 7 errors in 1.74s ========================
